<mujoco model="ball paddle">
  <option timestep="0.01" iterations="20" gravity="0 0 0"  integrator="Euler" />
  <default>
    <geom conaffinity="1" condim="3" density="100" friction="1 0.5 0.5" margin="0" rgba="0.8 0.6 0.4 1"/>
  </default>

  <worldbody>
    <light name="light" directional="true" diffuse=".6 .6 .6" pos="0 0 2" specular=".3 .3 .3"/>
    <geom name="ground" type="plane" pos="0 0 0" size=".6 .2 10" material="MatPlane"/>

    <body name="ball" pos="0 0 0">
      <joint axis="0 0 1" name="ballz" pos="0 0 0.3" type="slide"/>
      <geom name="ball" type="sphere" size=".025" solref="-1 -200"/>
    </body>
  </worldbody>

   <asset>
        <texture builtin="gradient" height="100" rgb1="1 1 1" rgb2="0 0 0" type="skybox" width="100"/>
        <texture builtin="flat" height="1278" mark="cross" markrgb="1 1 1" name="texgeom" random="0.01" rgb1="0.8 0.6 0.4" rgb2="0.8 0.6 0.4" type="cube" width="127"/>
        <texture builtin="checker" height="100" name="texplane" rgb1="0 0 0" rgb2="0.8 0.8 0.8" type="2d" width="100"/>
        <material name="MatPlane" reflectance="0.5" shininess="1" specular="1" texrepeat="30 30" texture="texplane"/>
        <material name="geom" texture="texgeom" texuniform="true"/>
    </asset>
</mujoco>